Workbook

Sheet Datos - Gastos
A1: Conceptos de gastos/ingresos | C1: Orígenes/destinos gastos e ingresos
A2: Pago Claude/Cursor | C2: Regalo recibida
A3: Salidas a cenar/almorzar | C3: Caja de seguridad
A4: Juntadas a cenar/almorzar | C4: Cta. Comitente Petrini
A5: Salidas a desyunar/merendar | C5: Superfondos Santander
A6: Juntadas a desayunar/merendar | C6: Caja de Ahorro Santander (ARS)
A7: Salidas a tomar algo | C7: Caja de Ahorro Santander (USD)
A8: Fiestas | C8: Mercado Pago
A9: Auto | C9: Brubank
A10: Celular | C10: Efectivo
A11: Farmacia/Cosméticos
A12: Ropa
A13: Súper
A14: Gimnasio
A15: Psicóloga
A16: Delivery
A17: Regalos
A18: Mascotas
A19: Entradas fiestas/conciertos/otros eventos
A20: Pago de honorarios Quantum
A21: Pago de honorarios Axis
A22: Otros honorarios
... A30: Compras varias

Sheet Gastos julio
B1: Datos del periodo | J1: Tenencia - Inicio | K1: USD | L1: ARS | N1: Tenencia - Fin | O1: USD | P1: ARS | R1: Diferencia | S1: USD | T1: ARS
B2: Año: | C2: 2026 | J2: Regalo recibida | K2: 10000 | L2: =K2*$D$7 -> 14890000 | N2: Regalo recibida | O2: =K2+SUMIF($E$24:$E$99,$N2,$C$24:$C$99)+SUMIF($E$24:$E$99,$N2,$D$24:$D$99) -> 10000 | P2: =O2*$D$7 -> 14890000 | R2: Regalo recibida | S2: =IFERROR(IF(O2>K2,O2-K2,K2-O2),0) -> 0 | T2: =IFERROR(IF(P2>L2,P2-L2,L2-P2),0) -> 0
B3: Mes: | C3: julio | J3: Caja de seguridad | K3: 500 | L3: =K3*$D$7 -> 744500 | N3: Caja de seguridad | O3: 500 | P3: =L3+SUMIF($E$24:$E$99,$N3,$C$24:$C$99)+SUMIF($E$24:$E$99,$N3,$D$24:$D$99) -> 744500 | R3: Caja de seguridad | S3: =IFERROR(IF(O3>K3,O3-K3,K3-O3),0) -> 0 | T3: =IFERROR(IF(P3>L3,P3-L3,L3-P3),0) -> 0
B4: Cantidad de días: | C4: =DAY(EOMONTH(DATE($C$2,MATCH($C$3,{"enero";"febrero";"marzo";"abril";"mayo";"junio";"julio";"agosto";"septiembre";"octubre";"noviembre";"diciembre"},0),1),0)) -> 31 | J4: Cta. Comitente Petrini | K4: =L4/$C$7 -> 302.20447 | L4: 447262.62 | N4: Cta. Comitente Petrini | O4: =IFERROR(P4/$C$8,"") -> 1128.2621 | P4: =L4+SUMIF($E$24:$E$99,$N4,$C$24:$C$99)+SUMIF($E$24:$E$99,$N4,$D$24:$D$99) -> 1647262.6 | R4: Cta. Comitente Petrini | S4: =IFERROR(IF(O4>K4,O4-K4,K4-O4),0) -> 826.0576 | T4: =IFERROR(IF(P4>L4,P4-L4,L4-P4),0) -> 1200000
J5: Superfondos Santander | K5: =L5/$C$7 -> 2160.0629 | L5: 3196893 | N5: Superfondos Santander | O5: =IFERROR(P5/$C$8,"") -> 929.01971 | P5: =L5+SUMIF($E$24:$E$99,$N5,$C$24:$C$99)+SUMIF($E$24:$E$99,$N5,$D$24:$D$99) -> 1356368.8 | R5: Superfondos Santander | S5: =IFERROR(IF(O5>K5,O5-K5,K5-O5),0) -> 1231.0432 | T5: =IFERROR(IF(P5>L5,P5-L5,L5-P5),0) -> 1840524.3
B6: Tc | C6: Compra | D6: Venta | J6: Caja de Ahorro Santander (ARS) | K6: =L6/$C$7 -> 253.20725 | L6: 374746.73 | N6: Caja de Ahorro Santander (ARS) | O6: =IFERROR(P6/$C$8,"") -> 1429.739 | P6: =L6+SUMIF($E$24:$E$99,$N6,$C$24:$C$99)+SUMIF($E$24:$E$99,$N6,$D$24:$D$99) -> 2087418.9 | R6: Caja de Ahorro Santander (ARS) | S6: =IFERROR(IF(O6>K6,O6-K6,K6-O6),0) -> 1176.5317 | T6: =IFERROR(IF(P6>L6,P6-L6,L6-P6),0) -> 1712672.2
B7: =DATE($C$2,MATCH($C$3,{"enero";"febrero";"marzo";"abril";"mayo";"junio";"julio";"agosto";"septiembre";"octubre";"noviembre";"diciembre"},0),1) -> 46204 | C7: 1480 | D7: 1489 | J7: Caja de Ahorro Santander (USD) | K7: 0.52 | L7: =K7*$D$7 -> 774.28 | N7: Caja de Ahorro Santander (USD) | O7: =K7+SUM(C17:C19)-SUM(D17:D19) -> 4.74 | P7: =O7*$D$8 -> 7157.4 | R7: Caja de Ahorro Santander (USD) | S7: =IFERROR(IF(O7>K7,O7-K7,K7-O7),0) -> 4.22 | T7: =IFERROR(IF(P7>L7,P7-L7,L7-P7),0) -> 6383.12
B8: =DATE($C$2,MATCH($C$3,{"enero";"febrero";"marzo";"abril";"mayo";"junio";"julio";"agosto";"septiembre";"octubre";"noviembre";"diciembre"},0),C4) -> 46234 | C8: 1460 | D8: 1510 | J8: Mercado Pago | K8: =L8/$C$7 -> 0.38181757 | L8: 565.09 | N8: Mercado Libre | O8: =IFERROR(P8/$C$8,"") -> 0.38704795 | P8: =L8+SUMIF($E$24:$E$99,$N8,$C$24:$C$99)+SUMIF($E$24:$E$99,$N8,$D$24:$D$99) -> 565.09 | R8: Mercado Libre | S8: =IFERROR(IF(O8>K8,O8-K8,K8-O8),0) -> 0.0052303776 | T8: =IFERROR(IF(P8>L8,P8-L8,L8-P8),0) -> 0
J9: Brubank | K9: =L9/$C$7 -> 0.00091891892 | L9: 1.36 | N9: Brubank | O9: =IFERROR(P9/$C$8,"") -> 0.00093150685 | P9: =L9+SUMIF($E$24:$E$99,$N9,$C$24:$C$99)+SUMIF($E$24:$E$99,$N9,$D$24:$D$99) -> 1.36 | R9: Brubank | S9: =IFERROR(IF(O9>K9,O9-K9,K9-O9),0) -> 1.258793e-05 | T9: =IFERROR(IF(P9>L9,P9-L9,L9-P9),0) -> 0
J10: Efectivo | K10: =L10/$C$7 -> 27.027027 | L10: 40000 | N10: Efectivo | O10: =IFERROR(P10/$C$8,"") -> 3.4246575 | P10: =L10+SUMIF($E$24:$E$99,$N10,$C$24:$C$99)+SUMIF($E$24:$E$99,$N10,$D$24:$D$99) -> 5000 | R10: Efectivo | S10: =IFERROR(IF(O10>K10,O10-K10,K10-O10),0) -> 23.602369 | T10: =IFERROR(IF(P10>L10,P10-L10,L10-P10),0) -> 35000
J12: Total | K12: =SUM(K2:K10) -> 13243.404 | L12: =SUM(L2:L10) -> 19694743 | N12: Total | O12: =SUM(O2:O9) -> 13992.149 | P12: =SUM(P2:P9) -> 20733274 | R12: Total | S12: =SUM(S2:S9) -> 3237.8577 | T12: =SUM(T2:T9) -> 4759579.6
B15: Compra/venta USD | J15: Análisis gastos e ingresos
B16: Nro. | C16: Ingresos | D16: Gastos | E16: Origen/Destino | F16: Concepto | G16: Descripción | H16: Fecha | J16: Concepto | K16: Acumulado egresos | L16: Acumulado ingresos | M16: Composición egresos | N16: Composición ingresos
B17: 1 | C17: 270 | E17: Caja de Ahorro Santander (USD) | F17: Pago tarjetas de crédito | G17: Compra USD p pagar tarjetas | H17: 46209 | J17: Pago Claude/Cursor | K17: =SUMIF($F$24:$F$99,$J17,$D$24:$D$99) -> 0 | L17: =SUMIF($F$24:$F$99,$J17,$C$24:$C$99) -> 16000 | M17: =IFERROR(K17/SUM(K$17:K$32),"") -> 0 | N17: =IFERROR(L17/SUM(L$17:L$32),"") -> 0.0040689308
B18: 2 | D18: 265.78 | E18: Caja de Ahorro Santander (USD) | F18: Pago tarjetas de crédito | G18: Pago tarjetas | H18: 46209 | J18: Salidas a cenar/almorzar | K18: =SUMIF($F$24:$F$99,$J18,$C$24:$C$99)+SUMIF($F$24:$F$99,$J18,$D$24:$D$99) -> -139930 | L18: =SUMIF($F$24:$F$99,$J18,$C$24:$C$99) -> 40050 | M18: =IFERROR(K18/SUM(K$17:K$32),"") -> -0.070832453 | N18: =IFERROR(L18/SUM(L$17:L$32),"") -> 0.010185042
J19: Salidas a desyunar/merendar | K19: =SUMIF($F$24:$F$99,$J19,$C$24:$C$99)+SUMIF($F$24:$F$99,$J19,$D$24:$D$99) -> -110800 | L19: =SUMIF($F$24:$F$99,$J19,$C$24:$C$99) -> 34200 | M19: =IFERROR(K19/SUM(K$17:K$32),"") -> -0.05608687 | N19: =IFERROR(L19/SUM(L$17:L$32),"") -> 0.0086973397
J20: Salidas a tomar algo | K20: =SUMIF($F$24:$F$99,$J20,$C$24:$C$99)+SUMIF($F$24:$F$99,$J20,$D$24:$D$99) -> -33000 | L20: =SUMIF($F$24:$F$99,$J20,$C$24:$C$99) -> 32000 | M20: =IFERROR(K20/SUM(K$17:K$32),"") -> -0.016704573 | N20: =IFERROR(L20/SUM(L$17:L$32),"") -> 0.0081378617
J21: Fiestas | K21: =SUMIF($F$24:$F$99,$J21,$C$24:$C$99)+SUMIF($F$24:$F$99,$J21,$D$24:$D$99) -> 0 | L21: =SUMIF($F$24:$F$99,$J21,$C$24:$C$99) -> 0 | M21: =IFERROR(K21/SUM(K$17:K$32),"") -> 0 | N21: =IFERROR(L21/SUM(L$17:L$32),"") -> 0
B22: Movimientos en ARS | J22: Auto | K22: =SUMIF($F$24:$F$99,$J22,$C$24:$C$99)+SUMIF($F$24:$F$99,$J22,$D$24:$D$99) -> -76600 | L22: =SUMIF($F$24:$F$99,$J22,$C$24:$C$99) -> 0 | M22: =IFERROR(K22/SUM(K$17:K$32),"") -> -0.038774858 | N22: =IFERROR(L22/SUM(L$17:L$32),"") -> 0
B23: Nro. | C23: Ingresos | D23: Gastos | E23: Origen/Destino | F23: Concepto | G23: Descripción | H23: Fecha | J23: Farmacia/Cosméticos | K23: =SUMIF($F$24:$F$99,$J23,$C$24:$C$99)+SUMIF($F$24:$F$99,$J23,$D$24:$D$99) -> -33852.49 | L23: =SUMIF($F$24:$F$99,$J23,$C$24:$C$99) -> 1439.91 | M23: =IFERROR(K23/SUM(K$17:K$32),"") -> -0.017136103 | N23: =IFERROR(L23/SUM(L$17:L$32),"") -> 0.00036618089
B24: 1 | D24: -18700 | E24: Efectivo | F24: Auto | G24: Cochera cumple Sofi H | H24: 46204 | J24: Ropa | K24: =SUMIF($F$24:$F$99,$J24,$C$24:$C$99)+SUMIF($F$24:$F$99,$J24,$D$24:$D$99) -> 0 | L24: =SUMIF($F$24:$F$99,$J24,$C$24:$C$99) -> 0 | M24: =IFERROR(K24/SUM(K$17:K$32),"") -> 0 | N24: =IFERROR(L24/SUM(L$17:L$32),"") -> 0
B25: 2 | C25: 16000 | E25: Caja de Ahorro Santander (ARS) | F25: Pago Claude/Cursor | G25: Transferencia IM | H25: 46205 | J25: Súper | K25: =SUMIF($F$24:$F$99,$J25,$C$24:$C$99)+SUMIF($F$24:$F$99,$J25,$D$24:$D$99) -> 0 | L25: =SUMIF($F$24:$F$99,$J25,$C$24:$C$99) -> 0 | M25: =IFERROR(K25/SUM(K$17:K$32),"") -> 0 | N25: =IFERROR(L25/SUM(L$17:L$32),"") -> 0
B26: 3 | D26: -4800 | E26: Caja de Ahorro Santander (ARS) | F26: Delivery | G26: Coca cena Sofi H | H26: 46205 | J26: Delivery | K26: =SUMIF($F$24:$F$99,$J26,$C$24:$C$99)+SUMIF($F$24:$F$99,$J26,$D$24:$D$99) -> -71557.6 | L26: =SUMIF($F$24:$F$99,$J26,$C$24:$C$99) -> 153000 | M26: =IFERROR(K26/SUM(K$17:K$32),"") -> -0.036222399 | N26: =IFERROR(L26/SUM(L$17:L$32),"") -> 0.038909151
B27: 4 | D27: -3900 | E27: Caja de Ahorro Santander (ARS) | F27: Auto | G27: Cochera | H27: 46205 | J27: Regalos | K27: =SUMIF($F$24:$F$99,$J27,$C$24:$C$99)+SUMIF($F$24:$F$99,$J27,$D$24:$D$99) -> 53200 | L27: =SUMIF($F$24:$F$99,$J27,$C$24:$C$99) -> 67500 | M27: =IFERROR(K27/SUM(K$17:K$32),"") -> 0.026929797 | N27: =IFERROR(L27/SUM(L$17:L$32),"") -> 0.017165802
B28: 5 | D28: -45759 | E28: Caja de Ahorro Santander (ARS) | F28: Delivery | G28: Comida cena Sofi H | H28: 46205 | J28: Entradas fiestas/conciertos | K28: =SUMIF($F$24:$F$99,$J28,$C$24:$C$99)+SUMIF($F$24:$F$99,$J28,$D$24:$D$99) -> 0 | L28: =SUMIF($F$24:$F$99,$J28,$C$24:$C$99) -> 0 | M28: =IFERROR(K28/SUM(K$17:K$32),"") -> 0 | N28: =IFERROR(L28/SUM(L$17:L$32),"") -> 0
B29: 6 | C29: 20000 | E29: Caja de Ahorro Santander (ARS) | F29: Delivery | G29: Dev. Lomito Sofi H | H29: 46205 | J29: Pago de honorarios Quantum | K29: =SUMIF($F$24:$F$99,$J29,$C$24:$C$99)+SUMIF($F$24:$F$99,$J29,$D$24:$D$99) -> 2084047 | L29: =SUMIF($F$24:$F$99,$J29,$C$24:$C$99) -> 2084047 | M29: =IFERROR(K29/SUM(K$17:K$32),"") -> 1.0549429 | N29: =IFERROR(L29/SUM(L$17:L$32),"") -> 0.52999019
B30: 7 | D30: -1000524.3 | E30: Superfondos Santander | F30: Rescates FCI | G30: Rescate p invertir en Petrini | H30: 46205 | J30: Pago de honorarios Axis | K30: =SUMIF($F$24:$F$99,$J30,$C$24:$C$99)+SUMIF($F$24:$F$99,$J30,$D$24:$D$99) -> 304000 | L30: =SUMIF($F$24:$F$99,$J30,$C$24:$C$99) -> 304000 | M30: =IFERROR(K30/SUM(K$17:K$32),"") -> 0.15388455 | N30: =IFERROR(L30/SUM(L$17:L$32),"") -> 0.077309686
B31: 8 | C31: 1000524.3 | E31: Caja de Ahorro Santander (ARS) | F31: Rescates FCI | G31: Rescate p invertir en Petrini | H31: 46205 | J31: Otros honorarios | K31: =SUMIF($F$24:$F$99,$J31,$C$24:$C$99)+SUMIF($F$24:$F$99,$J31,$D$24:$D$99) -> 0 | L31: =SUMIF($F$24:$F$99,$J31,$C$24:$C$99) -> 0 | M31: =IFERROR(K31/SUM(K$17:K$32),"") -> 0 | N31: =IFERROR(L31/SUM(L$17:L$32),"") -> 0
B32: 9 | D32: -1200000 | E32: Caja de Ahorro Santander (ARS) | F32: Ahorros/inversiones | G32: Transferencia a Petrini | H32: 46205 | J32: Ahorros/inversiones | K32: =SUMIF($F$24:$F$99,$J32,$C$24:$C$99)+SUMIF($F$24:$F$99,$J32,$D$24:$D$99) -> 0 | L32: =SUMIF($F$24:$F$99,$J32,$C$24:$C$99) -> 1200000 | M32: =IFERROR(K32/SUM(K$17:K$32),"") -> 0 | N32: =IFERROR(L32/SUM(L$17:L$32),"") -> 0.30516981
B33: 10 | C33: 1200000 | E33: Cta. Comitente Petrini | F33: Ahorros/inversiones | G33: Compra S&P 500 y fondo CER | H33: 46205 | J33: Pago tarjetas de crédito | K33: =SUMIF($F$24:$F$99,$J33,$C$24:$C$99)+SUMIF($F$24:$F$99,$J33,$D$24:$D$99) -> -692782.22 | L33: =SUMIF($F$24:$F$99,$J33,$C$24:$C$99) -> 3.62 | M33: =IFERROR(K33/SUM(K$17:K$32),"") -> -0.3506858 | N33: =IFERROR(L33/SUM(L$17:L$32),"") -> 9.205956e-07
B34: 11 | D34: -1000 | E34: Caja de Ahorro Santander (ARS) | F34: Auto | G34: Estacionamiento Chacana | H34: 46206
B35: 12 | D35: -27700 | E35: Caja de Ahorro Santander (ARS) | F35: Salidas a desyunar/merendar | G35: Desayuno Cielo Cherry Season | H35: 46207 | J35: Superfondos Santander
B36: 13 | D36: -43600 | E36: Caja de Ahorro Santander (ARS) | F36: Salidas a desyunar/merendar | G36: Merienda Parce IM, CA, IP | H36: 46207 | J36: Superfondos Santander | K36: 46209 | L36: 46216 | M36: 46223 | N36: 46230
B37: 14 | C37: 11200 | E37: Caja de Ahorro Santander (ARS) | F37: Salidas a desyunar/merendar | G37: Dev. Isa Parce | H37: 46207 | J37: Calculado | K37: =$L$5+SUMIFS($C$24:$C$99,$E$24:$E$99,$N5,$H$24:$H$99,"<"&K$36)+SUMIFS($D$24:$D$99,$E$24:$E$99,$N5,$H$24:$H$99,"<="&K$36) -> 1496368.8 | L37: =$L$5+SUMIFS($C$24:$C$99,$E$24:$E$99,$N5,$H$24:$H$99,"<"&L$36)+SUMIFS($D$24:$D$99,$E$24:$E$99,$N5,$H$24:$H$99,"<="&L$36) -> 1496368.8 | M37: =$L$5+SUMIFS($C$24:$C$99,$E$24:$E$99,$N5,$H$24:$H$99,"<"&M$36)+SUMIFS($D$24:$D$99,$E$24:$E$99,$N5,$H$24:$H$99,"<="&M$36) -> 1496368.8 | N37: =$L$5+SUMIFS($C$24:$C$99,$E$24:$E$99,$N5,$H$24:$H$99,"<"&N$36)+SUMIFS($D$24:$D$99,$E$24:$E$99,$N5,$H$24:$H$99,"<="&N$36) -> 1356368.8
B38: 15 | D38: -1300 | E38: Efectivo | F38: Regalos | G38: Semáforo | H38: 46207 | J38: Real | K38: 1496893 | L38: 1500051 | M38: 1506505.4 | N38: 1373248.7
B39: 16 | C39: 6000 | E39: Caja de Ahorro Santander (ARS) | F39: Salidas a desyunar/merendar | G39: Dev. Cielo Parce | H39: 46208 | J39: Rendimiento (neto) | K39: =IF(K38="","",K38-K37) -> 524.24 | L39: =IF(L38="","",L38-L37) -> 3682.2 | M39: =IF(M38="","",M38-M37) -> 10136.61 | N39: =IF(N38="","",N38-N37) -> 16879.9
B40: 17 | D40: -700000 | E40: Superfondos Santander | F40: Rescates FCI | G40: Rescate p comprar USD p pagar tarjeta de crédito | H40: 46209 | J40: Rendimiento (%) | K40: =IF(K39="","",((K38-K37)/K37)) -> 0.00035034145 | L40: =IF(L39="","",((L38-L37)/L37)) -> 0.002460757 | M40: =IF(M39="","",((M38-M37)/M37)) -> 0.006774139 | N40: =IF(N39="","",((N38-N37)/N37)) -> 0.012444919
B41: 18 | C41: 700000 | E41: Caja de Ahorro Santander (ARS) | F41: Rescates FCI | G41: Rescate p comprar USD p pagar tarjeta de crédito | H41: 46209
B42: 19 | D42: -280942.71 | E42: Caja de Ahorro Santander (ARS) | F42: Pago tarjetas de crédito | G42: Pago VISA ARS | H42: 46209 | J42: Petrini
B43: 20 | D43: -407700 | E43: Caja de Ahorro Santander (ARS) | F43: Pago tarjetas de crédito | G43: Compra USD para pago VISA y AMEX USD | H43: 46209 | J43: Fecha | K43: 46209 | L43: 46216 | M43: 46223 | N43: 46230
...

Sheet Gastos agosto
B1: Datos del periodo | J1: Tenencia - Inicio | K1: USD | L1: ARS | N1: Tenencia - Fin | O1: USD | P1: ARS | R1: Diferencia | S1: USD | T1: ARS
B2: Año: | C2: 2026 | J2: Regalo recibida | K2: ='Gastos julio'!O2 -> 10000 | L2: =K2*D7 -> 15100000 | N2: Regalo recibida | O2: =K2+SUMIF($E$24:$E$173,$N2,$C$24:$C$173)+SUMIF($E$24:$E$173,$N2,$D$24:$D$173) -> 10000 | P2: =O2*$D$7 -> 15100000 | R2: Regalo recibida | S2: =IFERROR(IF(O2>K2,O2-K2,K2-O2),0) -> 0 | T2: =IFERROR(IF(P2>L2,P2-L2,L2-P2),0) -> 0
B3: Mes: | C3: agosto | J3: Caja de seguridad | K3: ='Gastos julio'!O3 -> 500 | L3: =K3*D7 -> 755000 | N3: Caja de seguridad | O3: =K3 -> 500 | P3: =L3+SUMIF($E$24:$E$173,$N3,$C$24:$C$173)+SUMIF($E$24:$E$173,$N3,$D$24:$D$173) -> 755000 | R3: Caja de seguridad | S3: =IFERROR(IF(O3>K3,O3-K3,K3-O3),0) -> 0 | T3: =IFERROR(IF(P3>L3,P3-L3,L3-P3),0) -> 0
B4: Cantidad de días: | C4: =DAY(EOMONTH(DATE($C$2,MATCH($C$3,{"enero";"febrero";"marzo";"abril";"mayo";"junio";"julio";"agosto";"septiembre";"octubre";"noviembre";"diciembre"},0),1),0)) -> 31 | J4: Cta. Comitente Petrini | K4: ='Gastos julio'!O4 -> 1128.2621 | L4: ='Gastos julio'!P4 -> 1647262.6 | N4: Cta. Comitente Petrini | O4: =IFERROR(P4/$C$8,"") -> 1113.0153 | P4: =L4+SUMIF($E$24:$E$173,$N4,$C$24:$C$173)+SUMIF($E$24:$E$173,$N4,$D$24:$D$173) -> 1647262.6 | R4: Cta. Comitente Petrini | S4: =IFERROR(IF(O4>K4,O4-K4,K4-O4),0) -> 15.246785 | T4: =IFERROR(IF(P4>L4,P4-L4,L4-P4),0) -> 0
J5: Superfondos Santander | K5: ='Gastos julio'!O5 -> 929.01971 | L5: ='Gastos julio'!P5 -> 1356368.8 | N5: Superfondos Santander | O5: =IFERROR(P5/$C$8,"") -> 1950.2492 | P5: =L5+SUMIF($E$24:$E$173,$N5,$C$24:$C$173)+SUMIF($E$24:$E$173,$N5,$D$24:$D$173) -> 2886368.8 | R5: Superfondos Santander | S5: =IFERROR(IF(O5>K5,O5-K5,K5-O5),0) -> 1021.2295 | T5: =IFERROR(IF(P5>L5,P5-L5,L5-P5),0) -> 1530000
B6: Tc | C6: Compra | D6: Venta | J6: Caja de Ahorro Santander (ARS) | K6: ='Gastos julio'!O6 -> 1429.739 | L6: ='Gastos julio'!P6 -> 2087418.9 | N6: Caja de Ahorro Santander (ARS) | O6: =IFERROR(P6/$C$8,"") -> 1446.3709 | P6: =L6+SUMIF($E$24:$E$173,$N6,$C$24:$C$173)+SUMIF($E$24:$E$173,$N6,$D$24:$D$173) -> 2140629 | R6: Caja de Ahorro Santander (ARS) | S6: =IFERROR(IF(O6>K6,O6-K6,K6-O6),0) -> 16.631932 | T6: =IFERROR(IF(P6>L6,P6-L6,L6-P6),0) -> 53210.04
B7: =DATE($C$2,MATCH($C$3,{"enero";"febrero";"marzo";"abril";"mayo";"junio";"julio";"agosto";"septiembre";"octubre";"noviembre";"diciembre"},0),1) -> 46235 | C7: 1460 | D7: 1510 | J7: Caja de Ahorro Santander (USD) | K7: ='Gastos julio'!O7 -> 4.74 | L7: =K7*D7 -> 7157.4 | N7: Caja de Ahorro Santander (USD) | O7: =K7+SUM(C17:C19)+SUM(D17:D19) -> 9.91 | P7: =O7*$D$8 -> 15211.85 | R7: Caja de Ahorro Santander (USD) | S7: =IFERROR(IF(O7>K7,O7-K7,K7-O7),0) -> 5.17 | T7: =IFERROR(IF(P7>L7,P7-L7,L7-P7),0) -> 8054.45
B8: =DATE($C$2,MATCH($C$3,{"enero";"febrero";"marzo";"abril";"mayo";"junio";"julio";"agosto";"septiembre";"octubre";"noviembre";"diciembre"},0),C4) -> 46265 | C8: 1480 | D8: 1535 | J8: Mercado Pago | K8: ='Gastos julio'!O8 -> 0.38704795 | L8: ='Gastos julio'!P8 -> 565.09 | N8: Mercado Libre | O8: =IFERROR(P8/$C$8,"") -> 0.38181757 | P8: =L8+SUMIF($E$24:$E$173,$N8,$C$24:$C$173)+SUMIF($E$24:$E$173,$N8,$D$24:$D$173) -> 565.09 | R8: Mercado Libre | S8: =IFERROR(IF(O8>K8,O8-K8,K8-O8),0) -> 0.0052303776 | T8: =IFERROR(IF(P8>L8,P8-L8,L8-P8),0) -> 0
J9: Brubank | K9: ='Gastos julio'!O9 -> 0.00093150685 | L9: ='Gastos julio'!P9 -> 1.36 | N9: Brubank | O9: =IFERROR(P9/$C$8,"") -> 0.00091891892 | P9: =L9+SUMIF($E$24:$E$173,$N9,$C$24:$C$173)+SUMIF($E$24:$E$173,$N9,$D$24:$D$173) -> 1.36 | R9: Brubank | S9: =IFERROR(IF(O9>K9,O9-K9,K9-O9),0) -> 1.258793e-05 | T9: =IFERROR(IF(P9>L9,P9-L9,L9-P9),0) -> 0
J10: Efectivo | K10: ='Gastos julio'!O10 -> 3.4246575 | L10: ='Gastos julio'!P10 -> 5000 | N10: Efectivo | O10: =IFERROR(P10/$C$8,"") -> 0 | P10: =L10+SUMIF($E$24:$E$173,$N10,$C$24:$C$173)+SUMIF($E$24:$E$173,$N10,$D$24:$D$173) -> 0 | R10: Efectivo | S10: =IFERROR(IF(O10>K10,O10-K10,K10-O10),0) -> 3.4246575 | T10: =IFERROR(IF(P10>L10,P10-L10,L10-P10),0) -> 5000
J12: Total | K12: =SUM(K2:K10) -> 13995.573 | L12: =SUM(L2:L10) -> 20958774 | N12: Total | O12: =SUM(O2:O9) -> 15019.928 | P12: =SUM(P2:P9) -> 22545039 | R12: Total | S12: =SUM(S2:S9) -> 1058.2834 | T12: =SUM(T2:T9) -> 1591264.5
B15: Compra/venta USD | J15: Análisis gastos e ingresos
B16: Nro. | C16: Ingresos | D16: Gastos | E16: Origen/Destino | F16: Concepto | G16: Descripción | H16: Fecha | J16: Concepto | K16: Acumulado egresos | L16: Acumulado ingresos | M16: Composición egresos | N16: Composición ingresos
B17: 1 | C17: 52.3 | E17: Caja de Ahorro Santander (USD) | F17: Pago tarjetas de crédito | G17: Compra USD para pagos tarjetas de crédito | H17: 46244 | J17: Pago Claude/Cursor | K17: =SUMIF($F$24:$F$173,$J17,$D$24:$D$173) -> 0 | L17: =SUMIF($F$24:$F$173,$J17,$C$24:$C$173) -> 60150 | M17: =IFERROR(K17/SUM(K$17:K$32),"") -> 0 | N17: =IFERROR(L17/SUM(L$17:L$32),"") -> 0.017455166
B18: 2 | D18: -37.14 | E18: Caja de Ahorro Santander (USD) | F18: Pago tarjetas de crédito | G18: Pago VISA USD | H18: 46244 | J18: Salidas a cenar/almorzar | K18: =SUMIF($F$24:$F$173,$J18,$C$24:$C$173)+SUMIF($F$24:$F$173,$J18,$D$24:$D$173) -> -255130.74 | L18: =SUMIF($F$24:$F$173,$J18,$C$24:$C$173) -> 21000 | M18: =IFERROR(K18/SUM(K$17:K$32),"") -> -0.11892798 | N18: =IFERROR(L18/SUM(L$17:L$32),"") -> 0.0060940731
B19: 3 | D19: -9.99 | E19: Caja de Ahorro Santander (USD) | F19: Pago tarjetas de crédito | G19: Pago AMEX USD | H19: 46244 | J19: Salidas a desyunar/merendar | K19: =SUMIF($F$24:$F$173,$J19,$C$24:$C$173)+SUMIF($F$24:$F$173,$J19,$D$24:$D$173) -> -25100 | L19: =SUMIF($F$24:$F$173,$J19,$C$24:$C$173) -> 0 | M19: =IFERROR(K19/SUM(K$17:K$32),"") -> -0.011700246 | N19: =IFERROR(L19/SUM(L$17:L$32),"") -> 0
J20: Salidas a tomar algo | K20: =SUMIF($F$24:$F$173,$J20,$C$24:$C$173)+SUMIF($F$24:$F$173,$J20,$D$24:$D$173) -> -75330 | L20: =SUMIF($F$24:$F$173,$J20,$C$24:$C$173) -> 41370 | M20: =IFERROR(K20/SUM(K$17:K$32),"") -> -0.035114722 | N20: =IFERROR(L20/SUM(L$17:L$32),"") -> 0.012005324
J21: Fiestas | K21: =SUMIF($F$24:$F$173,$J21,$C$24:$C$173)+SUMIF($F$24:$F$173,$J21,$D$24:$D$173) -> -24600 | L21: =SUMIF($F$24:$F$173,$J21,$C$24:$C$173) -> 0 | M21: =IFERROR(K21/SUM(K$17:K$32),"") -> -0.011467173 | N21: =IFERROR(L21/SUM(L$17:L$32),"") -> 0
B22: Movimientos en ARS | J22: Auto | K22: =SUMIF($F$24:$F$173,$J22,$C$24:$C$173)+SUMIF($F$24:$F$173,$J22,$D$24:$D$173) -> -125000 | L22: =SUMIF($F$24:$F$173,$J22,$C$24:$C$173) -> 50000 | M22: =IFERROR(K22/SUM(K$17:K$32),"") -> -0.058268156 | N22: =IFERROR(L22/SUM(L$17:L$32),"") -> 0.014509698
B23: Nro. | C23: Ingresos | D23: Gastos | E23: Origen/Destino | F23: Concepto | G23: Descripción | H23: Fecha | J23: Farmacia/Cosméticos | K23: =SUMIF($F$24:$F$173,$J23,$C$24:$C$173)+SUMIF($F$24:$F$173,$J23,$D$24:$D$173) -> -6686.31 | L23: =SUMIF($F$24:$F$173,$J23,$C$24:$C$173) -> 0 | M23: =IFERROR(K23/SUM(K$17:K$32),"") -> -0.0031167916 | N23: =IFERROR(L23/SUM(L$17:L$32),"") -> 0
B24: 1 | D24: -10000 | E24: Caja de Ahorro Santander (ARS) | F24: Salidas a desyunar/merendar | G24: Torta hábito | H24: 46235 | J24: Ropa | K24: =SUMIF($F$24:$F$173,$J24,$C$24:$C$173)+SUMIF($F$24:$F$173,$J24,$D$24:$D$173) -> 0 | L24: =SUMIF($F$24:$F$173,$J24,$C$24:$C$173) -> 0 | M24: =IFERROR(K24/SUM(K$17:K$32),"") -> 0 | N24: =IFERROR(L24/SUM(L$17:L$32),"") -> 0
B25: 2 | D25: -61200 | E25: Caja de Ahorro Santander (ARS) | F25: Salidas a tomar algo | G25: Tresca sofias | H25: 46235 | J25: Súper | K25: =SUMIF($F$24:$F$173,$J25,$C$24:$C$173)+SUMIF($F$24:$F$173,$J25,$D$24:$D$173) -> 0 | L25: =SUMIF($F$24:$F$173,$J25,$C$24:$C$173) -> 0 | M25: =IFERROR(K25/SUM(K$17:K$32),"") -> 0 | N25: =IFERROR(L25/SUM(L$17:L$32),"") -> 0
B26: 3 | D26: -50000 | E26: Caja de Ahorro Santander (ARS) | F26: Auto | G26: Nafta | H26: 46236 | J26: Delivery | K26: =SUMIF($F$24:$F$173,$J26,$C$24:$C$173)+SUMIF($F$24:$F$173,$J26,$D$24:$D$173) -> -18000 | L26: =SUMIF($F$24:$F$173,$J26,$C$24:$C$173) -> 19500 | M26: =IFERROR(K26/SUM(K$17:K$32),"") -> -0.0083906145 | N26: =IFERROR(L26/SUM(L$17:L$32),"") -> 0.0056587822
B27: 4 | C27: 68500 | E27: Caja de Ahorro Santander (ARS) | F27: Pago de honorarios Axis | G27: Semana 5 julio | H27: 46236 | J27: Regalos | K27: =SUMIF($F$24:$F$173,$J27,$C$24:$C$173)+SUMIF($F$24:$F$173,$J27,$D$24:$D$173) -> -12850 | L27: =SUMIF($F$24:$F$173,$J27,$C$24:$C$173) -> 396000 | M27: =IFERROR(K27/SUM(K$17:K$32),"") -> -0.0059899664 | N27: =IFERROR(L27/SUM(L$17:L$32),"") -> 0.11491681
B28: 5 | C28: 29700 | E28: Caja de Ahorro Santander (ARS) | F28: Salidas a tomar algo | G28: Devolución So H tresca | H28: 46236 | J28: Entradas fiestas/conciertos | K28: =SUMIF($F$24:$F$173,$J28,$C$24:$C$173)+SUMIF($F$24:$F$173,$J28,$D$24:$D$173) -> 0 | L28: =SUMIF($F$24:$F$173,$J28,$C$24:$C$173) -> 0 | M28: =IFERROR(K28/SUM(K$17:K$32),"") -> 0 | N28: =IFERROR(L28/SUM(L$17:L$32),"") -> 0
B29: 6 | D29: -40000 | E29: Caja de Ahorro Santander (ARS) | F29: Salidas a cenar/almorzar | G29: Devolución Igna Std | H29: 46236 | J29: Pago de honorarios Quantum | K29: =SUMIF($F$24:$F$173,$J29,$C$24:$C$173)+SUMIF($F$24:$F$173,$J29,$D$24:$D$173) -> 2094451.1 | L29: =SUMIF($F$24:$F$173,$J29,$C$24:$C$173) -> 2094451.1 | M29: =IFERROR(K29/SUM(K$17:K$32),"") -> 0.97631845 | N29: =IFERROR(L29/SUM(L$17:L$32),"") -> 0.60779706
B30: 7 | D30: -5000 | E30: Efectivo | F30: Salidas a cenar/almorzar | G30: Propina | H30: 46236 | J30: Pago de honorarios Axis | K30: =SUMIF($F$24:$F$173,$J30,$C$24:$C$173)+SUMIF($F$24:$F$173,$J30,$D$24:$D$173) -> 423500 | L30: =SUMIF($F$24:$F$173,$J30,$C$24:$C$173) -> 423500 | M30: =IFERROR(K30/SUM(K$17:K$32),"") -> 0.19741251 | N30: =IFERROR(L30/SUM(L$17:L$32),"") -> 0.12289714
B31: 8 | C31: 1900000 | E31: Superfondos Santander | F31: Inversiones FCI | G31: Suscripción sueldo julio | H31: 46237 | J31: Otros honorarios | K31: =SUMIF($F$24:$F$173,$J31,$C$24:$C$173)+SUMIF($F$24:$F$173,$J31,$D$24:$D$173) -> 170000 | L31: =SUMIF($F$24:$F$173,$J31,$C$24:$C$173) -> 340000 | M31: =IFERROR(K31/SUM(K$17:K$32),"") -> 0.079244692 | N31: =IFERROR(L31/SUM(L$17:L$32),"") -> 0.098665945
B32: 9 | D32: -1900000 | E32: Caja de Ahorro Santander (ARS) | F32: Inversiones FCI | G32: Suscripción sueldo julio | H32: 46237 | J32: Ahorros/inversiones | K32: =SUMIF($F$24:$F$173,$J32,$C$24:$C$173)+SUMIF($F$24:$F$173,$J32,$D$24:$D$173) -> 0 | L32: =SUMIF($F$24:$F$173,$J32,$C$24:$C$173) -> 0 | M32: =IFERROR(K32/SUM(K$17:K$32),"") -> 0 | N32: =IFERROR(L32/SUM(L$17:L$32),"") -> 0
B33: 10 | D33: -20000 | E33: Caja de Ahorro Santander (ARS) | F33: Auto | G33: Lavado auto | H33: 46237 | J33: Pago tarjetas de crédito | K33: =SUMIF($F$24:$F$173,$J33,$C$24:$C$173)+SUMIF($F$24:$F$173,$J33,$D$24:$D$173) -> -309765.61 | L33: =SUMIF($F$24:$F$173,$J33,$C$24:$C$173) -> 52.3 | M33: =IFERROR(K33/SUM(K$17:K$32),"") -> -0.14439577 | N33: =IFERROR(L33/SUM(L$17:L$32),"") -> 1.5177144e-05
B34: 11 | D34: -35000 | E34: Caja de Ahorro Santander (ARS) | F34: Salidas a cenar/almorzar | G34: Edición 1: La cocina rica rica de Pacho | H34: 46238
B35: 12 | D35: -6686.31 | E35: Caja de Ahorro Santander (ARS) | F35: Farmacia/Cosméticos | G35: Tampones | H35: 46238 | J35: Superfondos Santander
B36: 13 | D36: -37500 | E36: Caja de Ahorro Santander (ARS) | F36: Delivery | G36: Burgers Igna | H36: 46238 | J36: Superfondos Santander | K36: 46237 | L36: 46244 | M36: 46251 | N36: 46258 | O36: 46265
B37: 14 | C37: 19500 | E37: Caja de Ahorro Santander (ARS) | F37: Delivery | G37: Dev burgers Igna | H37: 46238 | J37: Calculado | K37: =$L$5+SUMIFS($C$24:$C$173,$E$24:$E$173,$N5,$H$24:$H$173,"<="&K$36)+SUMIFS($D$24:$D$173,$E$24:$E$173,$N5,$H$24:$H$173,"<="&K$36) -> 3256368.8 | L37: =$L$5+SUMIFS($C$24:$C$173,$E$24:$E$173,$N5,$H$24:$H$173,"<"&L$36)+SUMIFS($D$24:$D$173,$E$24:$E$173,$N5,$H$24:$H$173,"<="&L$36) -> 2876368.8 | M37: =$L$5+SUMIFS($C$24:$C$173,$E$24:$E$173,$N5,$H$24:$H$173,"<"&M$36)+SUMIFS($D$24:$D$173,$E$24:$E$173,$N5,$H$24:$H$173,"<="&M$36) -> 3026368.8 | N37: =$L$5+SUMIFS($C$24:$C$173,$E$24:$E$173,$N5,$H$24:$H$173,"<"&N$36)+SUMIFS($D$24:$D$173,$E$24:$E$173,$N5,$H$24:$H$173,"<="&N$36) -> 2776368.8 | O37: =$L$5+SUMIFS($C$24:$C$173,$E$24:$E$173,$N5,$H$24:$H$173,"<"&O$36)+SUMIFS($D$24:$D$173,$E$24:$E$173,$N5,$H$24:$H$173,"<="&O$36) -> 2886368.8
B38: 15 | D38: -16900 | E38: Caja de Ahorro Santander (ARS) | F38: Salidas a cenar/almorzar | G38: Vino cena Nacho | H38: 46239 | J38: Real | K38: 3275661.5 | L38: 2905138.8 | M38: 3065231.6 | N38: 2826525.1 | O38: 2947715
B39: 16 | D39: -7000 | E39: Caja de Ahorro Santander (ARS) | F39: Celular | G39: Compra datos | H39: 46240 | J39: Rendimiento (neto) | K39: =IF(K38="","",K38-K37) -> 19292.69 | L39: =IF(L38="","",L38-L37) -> 28770 | M39: =IF(M38="","",M38-M37) -> 38862.82 | N39: =IF(N38="","",N38-N37) -> 50156.38 | O39: =IF(O38="","",O38-O37) -> 61346.18
B40: 17 | D40: -45000 | E40: Caja de Ahorro Santander (ARS) | F40: Psicóloga | G40: 1ra sesión agosto psico | H40: 46240 | J40: Rendimiento (%) | K40: =IF(K39="","",((K38-K37)/K37)) -> 0.0059246023 | L40: =IF(L39="","",((L38-L37)/L37)) -> 0.010002195 | M40: =IF(M39="","",((M38-M37)/M37)) -> 0.012841403 | N40: =IF(N39="","",((N38-N37)/N37)) -> 0.01806546 | O40: =IF(O39="","",((O38-O37)/O37)) -> 0.021253757
B41: 18 | D41: -80000 | E41: Superfondos Santander | F41: Rescates FCI | G41: Rescate p psico | H41: 46240
B42: 19 | C42: 80000 | E42: Caja de Ahorro Santander (ARS) | F42: Rescates FCI | G42: Rescate p psico | H42: 46240 | J42: Petrini
B43: 20 | D43: -14800 | E43: Caja de Ahorro Santander (ARS) | F43: Salidas a cenar/almorzar | G43: Lomitos 348 | H43: 46240 | J43: Fecha | K43: 46237 | L43: 46244 | M43: 46251 | N43: 46258 | O43: 46265
...

Sheet Gastos septiembre
B1: Datos del periodo | J1: Tenencia - Inicio | K1: USD | L1: ARS | N1: Tenencia - Fin | O1: USD | P1: ARS | R1: Diferencia | S1: USD | T1: ARS
B2: Año: | C2: 2026 | J2: Regalo recibida | K2: ='Gastos agosto'!O2 -> 10000 | L2: =K2*D7 -> 15350000 | N2: Regalo recibida | O2: =K2+SUMIF($E$24:$E$173,$N2,$C$24:$C$173)+SUMIF($E$24:$E$173,$N2,$D$24:$D$173) -> 10000 | P2: =O2*$D$7 -> 15350000 | R2: Regalo recibida | S2: =IFERROR(IF(O2>K2,O2-K2,K2-O2),0) -> 0 | T2: =IFERROR(IF(P2>L2,P2-L2,L2-P2),0) -> 0
B3: Mes: | C3: septiembre | J3: Caja de seguridad | K3: ='Gastos agosto'!O3 -> 500 | L3: =K3*D7 -> 767500 | N3: Caja de seguridad | O3: =K3 -> 500 | P3: =L3+SUMIF($E$24:$E$173,$N3,$C$24:$C$173)+SUMIF($E$24:$E$173,$N3,$D$24:$D$173) -> 767500 | R3: Caja de seguridad | S3: =IFERROR(IF(O3>K3,O3-K3,K3-O3),0) -> 0 | T3: =IFERROR(IF(P3>L3,P3-L3,L3-P3),0) -> 0
B4: Cantidad de días: | C4: =DAY(EOMONTH(DATE($C$2,MATCH($C$3,{"enero";"febrero";"marzo";"abril";"mayo";"junio";"julio";"agosto";"septiembre";"octubre";"noviembre";"diciembre"},0),1),0)) -> 30 | J4: Cta. Comitente Petrini | K4: ='Gastos agosto'!O4 -> 1113.0153 | L4: ='Gastos agosto'!P4 -> 1647262.6 | N4: Cta. Comitente Petrini | O4: =IFERROR(P4/$C$8,"") | P4: =L4+SUMIF($E$24:$E$173,$N4,$C$24:$C$173)+SUMIF($E$24:$E$173,$N4,$D$24:$D$173) -> 1647262.6 | R4: Cta. Comitente Petrini | S4: =IFERROR(IF(O4>K4,O4-K4,K4-O4),0) -> 0 | T4: =IFERROR(IF(P4>L4,P4-L4,L4-P4),0) -> 0
J5: Superfondos Santander | K5: ='Gastos agosto'!O5 -> 1950.2492 | L5: ='Gastos agosto'!P5 -> 2886368.8 | N5: Superfondos Santander | O5: =IFERROR(P5/$C$8,"") | P5: =L5+SUMIF($E$24:$E$173,$N5,$C$24:$C$173)+SUMIF($E$24:$E$173,$N5,$D$24:$D$173) -> 3896368.8 | R5: Superfondos Santander | S5: =IFERROR(IF(O5>K5,O5-K5,K5-O5),0) -> 0 | T5: =IFERROR(IF(P5>L5,P5-L5,L5-P5),0) -> 1010000
B6: Tc (BNA) | C6: Compra | D6: Venta | J6: Caja de Ahorro Santander (ARS) | K6: ='Gastos agosto'!O6 -> 1446.3709 | L6: ='Gastos agosto'!P6 -> 2140629 | N6: Caja de Ahorro Santander (ARS) | O6: =IFERROR(P6/$C$8,"") | P6: =L6+SUMIF($E$24:$E$173,$N6,$C$24:$C$173)+SUMIF($E$24:$E$173,$N6,$D$24:$D$173) -> 5648.43 | R6: Caja de Ahorro Santander (ARS) | S6: =IFERROR(IF(O6>K6,O6-K6,K6-O6),0) -> 0 | T6: =IFERROR(IF(P6>L6,P6-L6,L6-P6),0) -> 2134980.6
B7: =DATE($C$2,MATCH($C$3,{"enero";"febrero";"marzo";"abril";"mayo";"junio";"julio";"agosto";"septiembre";"octubre";"noviembre";"diciembre"},0),1) -> 46266 | C7: 1485 | D7: 1535 | J7: Caja de Ahorro Santander (USD) | K7: ='Gastos agosto'!O7 -> 9.91 | L7: =K7*D7 -> 15211.85 | N7: Caja de Ahorro Santander (USD) | O7: =K7+SUM(C17:C19)+SUM(D17:D19) -> 1.88 | P7: =O7*$D$8 -> 0 | R7: Caja de Ahorro Santander (USD) | S7: =IFERROR(IF(O7>K7,O7-K7,K7-O7),0) -> 8.03 | T7: =IFERROR(IF(P7>L7,P7-L7,L7-P7),0) -> 15211.85
B8: =DATE($C$2,MATCH($C$3,{"enero";"febrero";"marzo";"abril";"mayo";"junio";"julio";"agosto";"septiembre";"octubre";"noviembre";"diciembre"},0),C4) -> 46295 | J8: Mercado Pago | K8: ='Gastos agosto'!O8 -> 0.38181757 | L8: ='Gastos agosto'!P8 -> 565.09 | N8: Mercado Libre | O8: =IFERROR(P8/$C$8,"") | P8: =L8+SUMIF($E$24:$E$173,$N8,$C$24:$C$173)+SUMIF($E$24:$E$173,$N8,$D$24:$D$173) -> 565.09 | R8: Mercado Libre | S8: =IFERROR(IF(O8>K8,O8-K8,K8-O8),0) -> 0 | T8: =IFERROR(IF(P8>L8,P8-L8,L8-P8),0) -> 0
J9: Brubank | K9: ='Gastos agosto'!O9 -> 0.00091891892 | L9: ='Gastos agosto'!P9 -> 1.36 | N9: Brubank | O9: =IFERROR(P9/$C$8,"") | P9: =L9+SUMIF($E$24:$E$173,$N9,$C$24:$C$173)+SUMIF($E$24:$E$173,$N9,$D$24:$D$173) -> 1.36 | R9: Brubank | S9: =IFERROR(IF(O9>K9,O9-K9,K9-O9),0) -> 0 | T9: =IFERROR(IF(P9>L9,P9-L9,L9-P9),0) -> 0
J10: Efectivo | K10: ='Gastos agosto'!O10 -> 0 | L10: ='Gastos agosto'!P10 -> 0 | N10: Efectivo | O10: =IFERROR(P10/$C$8,"") | P10: =L10+SUMIF($E$24:$E$173,$N10,$C$24:$C$173)+SUMIF($E$24:$E$173,$N10,$D$24:$D$173) -> 32600 | R10: Efectivo | S10: =IFERROR(IF(O10>K10,O10-K10,K10-O10),0) -> 0 | T10: =IFERROR(IF(P10>L10,P10-L10,L10-P10),0) -> 32600
J12: Total | K12: =SUM(K2:K10) -> 15019.928 | L12: =SUM(L2:L10) -> 22807539 | N12: Total | O12: =SUM(O2:O9) -> 10501.88 | P12: =SUM(P2:P9) -> 21667346 | R12: Total | S12: =SUM(S2:S9) -> 8.03 | T12: =SUM(T2:T9) -> 3160192.4
B15: Compra/venta USD | J15: Análisis gastos e ingresos
B16: Nro. | C16: Ingresos | D16: Gastos | E16: Origen/Destino | F16: Concepto | G16: Descripción | H16: Fecha | J16: Concepto | K16: Acumulado egresos | L16: Acumulado ingresos | M16: Composición egresos | N16: Composición ingresos
B17: 1 | C17: 50 | E17: Caja de Ahorro Santander (USD) | F17: Pago tarjetas de crédito | G17: Compra USD para pagos tarjetas de crédito | H17: 46268 | J17: Pago Claude/Cursor | K17: =SUMIF($F$24:$F$173,$J17,$D$24:$D$173) -> 0 | L17: =SUMIF($F$24:$F$173,$J17,$C$24:$C$173) -> 0 | M17: =IFERROR(K17/SUM(K$17:K$32),"") -> 0 | N17: =IFERROR(L17/SUM(L$17:L$32),"") -> 0
B18: 2 | D18: -48.04 | E18: Caja de Ahorro Santander (USD) | F18: Pago tarjetas de crédito | G18: Pago VISA USD | H18: 46268 | J18: Salidas a cenar/almorzar | K18: =SUMIF($F$24:$F$173,$J18,$C$24:$C$173)+SUMIF($F$24:$F$173,$J18,$D$24:$D$173) -> -39300 | L18: =SUMIF($F$24:$F$173,$J18,$C$24:$C$173) -> 0 | M18: =IFERROR(K18/SUM(K$17:K$32),"") -> 0.33558675 | N18: =IFERROR(L18/SUM(L$17:L$32),"") -> 0
B19: 3 | D19: -9.99 | E19: Caja de Ahorro Santander (USD) | F19: Pago tarjetas de crédito | G19: Pago AMEX USD | H19: 46268 | J19: Salidas a desyunar/merendar | K19: =SUMIF($F$24:$F$173,$J19,$C$24:$C$173)+SUMIF($F$24:$F$173,$J19,$D$24:$D$173) -> -55400 | L19: =SUMIF($F$24:$F$173,$J19,$C$24:$C$173) -> 0 | M19: =IFERROR(K19/SUM(K$17:K$32),"") -> 0.4730663 | N19: =IFERROR(L19/SUM(L$17:L$32),"") -> 0
J20: Salidas a tomar algo | K20: =SUMIF($F$24:$F$173,$J20,$C$24:$C$173)+SUMIF($F$24:$F$173,$J20,$D$24:$D$173) -> -71900 | L20: =SUMIF($F$24:$F$173,$J20,$C$24:$C$173) -> 0 | M20: =IFERROR(K20/SUM(K$17:K$32),"") -> 0.6139615 | N20: =IFERROR(L20/SUM(L$17:L$32),"") -> 0
J21: Fiestas | K21: =SUMIF($F$24:$F$173,$J21,$C$24:$C$173)+SUMIF($F$24:$F$173,$J21,$D$24:$D$173) -> 0 | L21: =SUMIF($F$24:$F$173,$J21,$C$24:$C$173) -> 0 | M21: =IFERROR(K21/SUM(K$17:K$32),"") -> 0 | N21: =IFERROR(L21/SUM(L$17:L$32),"") -> 0
B22: Movimientos en ARS | J22: Auto | K22: =SUMIF($F$24:$F$173,$J22,$C$24:$C$173)+SUMIF($F$24:$F$173,$J22,$D$24:$D$173) -> -56000 | L22: =SUMIF($F$24:$F$173,$J22,$C$24:$C$173) -> 220000 | M22: =IFERROR(K22/SUM(K$17:K$32),"") -> 0.47818976 | N22: =IFERROR(L22/SUM(L$17:L$32),"") -> 0.43912176
B23: Nro. | C23: Ingresos | D23: Gastos | E23: Origen/Destino | F23: Concepto | G23: Descripción | H23: Fecha | J23: Farmacia/Cosméticos | K23: =SUMIF($F$24:$F$173,$J23,$C$24:$C$173)+SUMIF($F$24:$F$173,$J23,$D$24:$D$173) -> -21560.32 | L23: =SUMIF($F$24:$F$173,$J23,$C$24:$C$173) -> 0 | M23: =IFERROR(K23/SUM(K$17:K$32),"") -> 0.18410579 | N23: =IFERROR(L23/SUM(L$17:L$32),"") -> 0
B24: 1 | D24: -50000 | E24: Caja de Ahorro Santander (ARS) | F24: Auto | G24: Nafta | H24: 46266 | J24: Ropa | K24: =SUMIF($F$24:$F$173,$J24,$C$24:$C$173)+SUMIF($F$24:$F$173,$J24,$D$24:$D$173) -> 0 | L24: =SUMIF($F$24:$F$173,$J24,$C$24:$C$173) -> 0 | M24: =IFERROR(K24/SUM(K$17:K$32),"") -> 0 | N24: =IFERROR(L24/SUM(L$17:L$32),"") -> 0
B25: 2 | D25: -6686.32 | E25: Caja de Ahorro Santander (ARS) | F25: Farmacia/Cosméticos | G25: Tampones | H25: 46266 | J25: Súper | K25: =SUMIF($F$24:$F$173,$J25,$C$24:$C$173)+SUMIF($F$24:$F$173,$J25,$D$24:$D$173) -> -34048 | L25: =SUMIF($F$24:$F$173,$J25,$C$24:$C$173) -> 20000 | M25: =IFERROR(K25/SUM(K$17:K$32),"") -> 0.29073938 | N25: =IFERROR(L25/SUM(L$17:L$32),"") -> 0.03992016
B26: 3 | D26: -20000 | E26: Caja de Ahorro Santander (ARS) | F26: Regalos | G26: Lavado auto Jo | H26: 46266 | J26: Delivery | K26: =SUMIF($F$24:$F$173,$J26,$C$24:$C$173)+SUMIF($F$24:$F$173,$J26,$D$24:$D$173) -> 0 | L26: =SUMIF($F$24:$F$173,$J26,$C$24:$C$173) -> 0 | M26: =IFERROR(K26/SUM(K$17:K$32),"") -> 0 | N26: =IFERROR(L26/SUM(L$17:L$32),"") -> 0
B27: 4 | C27: 2000000 | E27: Superfondos Santander | F27: Inversiones FCI | G27: Suscripción honorarios agosto | H27: 46266 | J27: Regalos | K27: =SUMIF($F$24:$F$173,$J27,$C$24:$C$173)+SUMIF($F$24:$F$173,$J27,$D$24:$D$173) -> -39900 | L27: =SUMIF($F$24:$F$173,$J27,$C$24:$C$173) -> 60000 | M27: =IFERROR(K27/SUM(K$17:K$32),"") -> 0.34071021 | N27: =IFERROR(L27/SUM(L$17:L$32),"") -> 0.11976048
B28: 5 | D28: -2000000 | E28: Caja de Ahorro Santander (ARS) | F28: Inversiones FCI | G28: Suscripción honorarios agosto | H28: 46266 | J28: Entradas fiestas/conciertos | K28: =SUMIF($F$24:$F$173,$J28,$C$24:$C$173)+SUMIF($F$24:$F$173,$J28,$D$24:$D$173) -> 0 | L28: =SUMIF($F$24:$F$173,$J28,$C$24:$C$173) -> 0 | M28: =IFERROR(K28/SUM(K$17:K$32),"") -> 0 | N28: =IFERROR(L28/SUM(L$17:L$32),"") -> 0
B29: 6 | D29: -22500 | E29: Caja de Ahorro Santander (ARS) | F29: Juntadas a cenar/almorzar | G29: Sushi cielo y brana | H29: 46266 | J29: Pago de honorarios Quantum | K29: =SUMIF($F$24:$F$173,$J29,$C$24:$C$173)+SUMIF($F$24:$F$173,$J29,$D$24:$D$173) -> 0 | L29: =SUMIF($F$24:$F$173,$J29,$C$24:$C$173) -> 0 | M29: =IFERROR(K29/SUM(K$17:K$32),"") -> 0 | N29: =IFERROR(L29/SUM(L$17:L$32),"") -> 0
B30: 7 | D30: -10000 | E30: Caja de Ahorro Santander (ARS) | F30: Juntadas a cenar/almorzar | G30: Cochera cena cielo y bra | H30: 46266 | J30: Pago de honorarios Axis | K30: =SUMIF($F$24:$F$173,$J30,$C$24:$C$173)+SUMIF($F$24:$F$173,$J30,$D$24:$D$173) -> 201000 | L30: =SUMIF($F$24:$F$173,$J30,$C$24:$C$173) -> 201000 | M30: =IFERROR(K30/SUM(K$17:K$32),"") -> -1.7163597 | N30: =IFERROR(L30/SUM(L$17:L$32),"") -> 0.4011976
B31: 8 | D31: -4900 | E31: Caja de Ahorro Santander (ARS) | F31: Súper | G31: Panadería Cofico | H31: 46267 | J31: Otros honorarios | K31: =SUMIF($F$24:$F$173,$J31,$C$24:$C$173)+SUMIF($F$24:$F$173,$J31,$D$24:$D$173) -> 0 | L31: =SUMIF($F$24:$F$173,$J31,$C$24:$C$173) -> 0 | M31: =IFERROR(K31/SUM(K$17:K$32),"") -> 0 | N31: =IFERROR(L31/SUM(L$17:L$32),"") -> 0
B32: 9 | D32: -14874 | E32: Caja de Ahorro Santander (ARS) | F32: Farmacia/Cosméticos | G32: Corega tabs e hilo dental | H32: 46268 | J32: Ahorros/inversiones | K32: =SUMIF($F$24:$F$173,$J32,$C$24:$C$173)+SUMIF($F$24:$F$173,$J32,$D$24:$D$173) -> 0 | L32: =SUMIF($F$24:$F$173,$J32,$C$24:$C$173) -> 0 | M32: =IFERROR(K32/SUM(K$17:K$32),"") -> 0 | N32: =IFERROR(L32/SUM(L$17:L$32),"") -> 0
B33: 10 | C33: 30000 | E33: Efectivo | F33: Mascotas | G33: Devolución cucha | H33: 46268 | J33: Pago tarjetas de crédito | K33: =SUMIF($F$24:$F$173,$J33,$C$24:$C$173)+SUMIF($F$24:$F$173,$J33,$D$24:$D$173) -> -336416.98 | L33: =SUMIF($F$24:$F$173,$J33,$C$24:$C$173) -> 50 | M33: =IFERROR(K33/SUM(K$17:K$32),"") -> 2.8726992 | N33: =IFERROR(L33/SUM(L$17:L$32),"") -> 9.9800399e-05
B34: 11 | D34: -500000 | E34: Superfondos Santander | F34: Rescates FCI | G34: Rescate p pagar tarjetas de crédito | H34: 46268
B35: 12 | C35: 500000 | E35: Caja de Ahorro Santander (ARS) | F35: Rescates FCI | G35: Rescate p pagar tarjetas de crédito | H35: 46268 | J35: Superfondos Santander
B36: 13 | D36: -46000 | E36: Caja de Ahorro Santander (ARS) | F36: Entradas fiestas/conciertos/otros eventos | G36: An Espil x2 entradas | H36: 46268 | J36: Superfondos Santander | K36: 46272 | L36: 46279 | M36: 46286 | N36: 46293
B37: 14 | D37: -255875.44 | E37: Caja de Ahorro Santander (ARS) | F37: Pago tarjetas de crédito | G37: VISA ARS agosto | H37: 46268 | J37: Calculado | K37: =$L$5+SUMIFS($C$24:$C$173,$E$24:$E$173,$N5,$H$24:$H$173,"<="&K$36)+SUMIFS($D$24:$D$173,$E$24:$E$173,$N5,$H$24:$H$173,"<="&K$36) -> 4386368.8 | L37: =$L$5+SUMIFS($C$24:$C$173,$E$24:$E$173,$N5,$H$24:$H$173,"<"&L$36)+SUMIFS($D$24:$D$173,$E$24:$E$173,$N5,$H$24:$H$173,"<="&L$36) -> 3986368.8 | M37: =$L$5+SUMIFS($C$24:$C$173,$E$24:$E$173,$N5,$H$24:$H$173,"<"&M$36)+SUMIFS($D$24:$D$173,$E$24:$E$173,$N5,$H$24:$H$173,"<="&M$36) -> 3896368.8 | N37: =$L$5+SUMIFS($C$24:$C$173,$E$24:$E$173,$N5,$H$24:$H$173,"<"&N$36)+SUMIFS($D$24:$D$173,$E$24:$E$173,$N5,$H$24:$H$173,"<="&N$36) -> 3896368.8
B38: 15 | D38: -76500 | E38: Caja de Ahorro Santander (ARS) | F38: Pago tarjetas de crédito | G38: Compra USD p tarjetas | H38: 46268 | J38: Real | K38: 4462218.8 | L38: 4078252.3
B39: 16 | C39: 50 | E39: Caja de Ahorro Santander (USD) | F39: Pago tarjetas de crédito | G39: Compra USD para pagos tarjetas de crédito | H39: 46268 | J39: Rendimiento (neto) | K39: =IF(K38="","",K38-K37) -> 75850.08 | L39: =IF(L38="","",L38-L37) -> 91883.57 | M39: =IF(M38="","",M38-M37) | N39: =IF(N38="","",N38-N37)
B40: 17 | D40: -48.04 | E40: Caja de Ahorro Santander (USD) | F40: Pago tarjetas de crédito | G40: Pago VISA USD | H40: 46268 | J40: Rendimiento (%) | K40: =IF(K39="","",((K38-K37)/K37)) -> 0.017292226 | L40: =IF(L39="","",((L38-L37)/L37)) -> 0.023049441 | M40: =IF(M39="","",((M38-M37)/M37)) | N40: =IF(N39="","",((N38-N37)/N37))
B41: 18 | D41: -9.99 | E41: Caja de Ahorro Santander (USD) | F41: Pago tarjetas de crédito | G41: Pago AMEX USD | H41: 46268
B42: 19 | D42: -4033.51 | E42: Caja de Ahorro Santander (ARS) | F42: Pago tarjetas de crédito | G42: Pago AMEX ARS | H42: 46268 | J42: Petrini
B43: 20 | D43: -116670 | E43: Caja de Ahorro Santander (ARS) | F43: Entradas fiestas/conciertos/otros eventos | G43: Service charge y cuota 1 CR2027 | H43: 46268 | J43: Fecha | K43: =K36 -> 46272 | L43: =L36 -> 46279 | M43: =M36 -> 46286 | N43: =N36 -> 46293
...

Sheet Gastos octubre
B1: Datos del periodo | J1: Tenencia - Inicio | K1: USD | L1: ARS | N1: Tenencia - Fin | O1: USD | P1: ARS | R1: Diferencia | S1: USD | T1: ARS
B2: Año: | C2: 2026 | J2: Regalo recibida | K2: ='Gastos septiembre'!O2 -> 10000 | L2: =K2*D7 -> 0 | N2: Regalo recibida | O2: =K2+SUMIF($E$24:$E$173,$N2,$C$24:$C$173)+SUMIF($E$24:$E$173,$N2,$D$24:$D$173) -> 10000 | P2: =O2*$D$7 -> 0 | R2: Regalo recibida | S2: =IFERROR(IF(O2>K2,O2-K2,K2-O2),0) -> 0 | T2: =IFERROR(IF(P2>L2,P2-L2,L2-P2),0) -> 0
B3: Mes: | C3: octubre | J3: Caja de seguridad | K3: ='Gastos septiembre'!O3 -> 500 | L3: =K3*D7 -> 0 | N3: Caja de seguridad | O3: =K3 -> 500 | P3: =L3+SUMIF($E$24:$E$173,$N3,$C$24:$C$173)+SUMIF($E$24:$E$173,$N3,$D$24:$D$173) -> 0 | R3: Caja de seguridad | S3: =IFERROR(IF(O3>K3,O3-K3,K3-O3),0) -> 0 | T3: =IFERROR(IF(P3>L3,P3-L3,L3-P3),0) -> 0
B4: Cantidad de días: | C4: =DAY(EOMONTH(DATE($C$2,MATCH($C$3,{"enero";"febrero";"marzo";"abril";"mayo";"junio";"julio";"agosto";"septiembre";"octubre";"noviembre";"diciembre"},0),1),0)) -> 31 | J4: Cta. Comitente Petrini | K4: ='Gastos septiembre'!O4 | L4: ='Gastos septiembre'!P4 -> 1647262.6 | N4: Cta. Comitente Petrini | O4: =IFERROR(P4/$C$8,"") | P4: =L4+SUMIF($E$24:$E$173,$N4,$C$24:$C$173)+SUMIF($E$24:$E$173,$N4,$D$24:$D$173) -> 1647262.6 | R4: Cta. Comitente Petrini | S4: =IFERROR(IF(O4>K4,O4-K4,K4-O4),0) -> 0 | T4: =IFERROR(IF(P4>L4,P4-L4,L4-P4),0) -> 0
J5: Superfondos Santander | K5: ='Gastos septiembre'!O5 | L5: ='Gastos septiembre'!P5 -> 3896368.8 | N5: Superfondos Santander | O5: =IFERROR(P5/$C$8,"") | P5: =L5+SUMIF($E$24:$E$173,$N5,$C$24:$C$173)+SUMIF($E$24:$E$173,$N5,$D$24:$D$173) -> 3896368.8 | R5: Superfondos Santander | S5: =IFERROR(IF(O5>K5,O5-K5,K5-O5),0) -> 0 | T5: =IFERROR(IF(P5>L5,P5-L5,L5-P5),0) -> 0
B6: Tc | C6: Compra | D6: Venta | J6: Caja de Ahorro Santander (ARS) | K6: ='Gastos septiembre'!O6 | L6: ='Gastos septiembre'!P6 -> 5648.43 | N6: Caja de Ahorro Santander (ARS) | O6: =IFERROR(P6/$C$8,"") | P6: =L6+SUMIF($E$24:$E$173,$N6,$C$24:$C$173)+SUMIF($E$24:$E$173,$N6,$D$24:$D$173) -> 5648.43 | R6: Caja de Ahorro Santander (ARS) | S6: =IFERROR(IF(O6>K6,O6-K6,K6-O6),0) -> 0 | T6: =IFERROR(IF(P6>L6,P6-L6,L6-P6),0) -> 0
B7: =DATE($C$2,MATCH($C$3,{"enero";"febrero";"marzo";"abril";"mayo";"junio";"julio";"agosto";"septiembre";"octubre";"noviembre";"diciembre"},0),1) -> 46296 | J7: Caja de Ahorro Santander (USD) | K7: ='Gastos septiembre'!O7 -> 1.88 | L7: =K7*D7 -> 0 | N7: Caja de Ahorro Santander (USD) | O7: =K7+SUM(C17:C19)+SUM(D17:D19) -> 1.88 | P7: =O7*$D$8 -> 0 | R7: Caja de Ahorro Santander (USD) | S7: =IFERROR(IF(O7>K7,O7-K7,K7-O7),0) -> 0 | T7: =IFERROR(IF(P7>L7,P7-L7,L7-P7),0) -> 0
B8: =DATE($C$2,MATCH($C$3,{"enero";"febrero";"marzo";"abril";"mayo";"junio";"julio";"agosto";"septiembre";"octubre";"noviembre";"diciembre"},0),C4) -> 46326 | J8: Mercado Pago | K8: ='Gastos septiembre'!O8 | L8: ='Gastos septiembre'!P8 -> 565.09 | N8: Mercado Libre | O8: =IFERROR(P8/$C$8,"") | P8: =L8+SUMIF($E$24:$E$173,$N8,$C$24:$C$173)+SUMIF($E$24:$E$173,$N8,$D$24:$D$173) -> 565.09 | R8: Mercado Libre | S8: =IFERROR(IF(O8>K8,O8-K8,K8-O8),0) -> 0 | T8: =IFERROR(IF(P8>L8,P8-L8,L8-P8),0) -> 0
J9: Brubank | K9: ='Gastos septiembre'!O9 | L9: ='Gastos septiembre'!P9 -> 1.36 | N9: Brubank | O9: =IFERROR(P9/$C$8,"") | P9: =L9+SUMIF($E$24:$E$173,$N9,$C$24:$C$173)+SUMIF($E$24:$E$173,$N9,$D$24:$D$173) -> 1.36 | R9: Brubank | S9: =IFERROR(IF(O9>K9,O9-K9,K9-O9),0) -> 0 | T9: =IFERROR(IF(P9>L9,P9-L9,L9-P9),0) -> 0
J10: Efectivo | K10: ='Gastos septiembre'!O10 | L10: ='Gastos septiembre'!P10 -> 32600 | N10: Efectivo | O10: =IFERROR(P10/$C$8,"") | P10: =L10+SUMIF($E$24:$E$173,$N10,$C$24:$C$173)+SUMIF($E$24:$E$173,$N10,$D$24:$D$173) -> 32600 | R10: Efectivo | S10: =IFERROR(IF(O10>K10,O10-K10,K10-O10),0) -> 0 | T10: =IFERROR(IF(P10>L10,P10-L10,L10-P10),0) -> 0
J12: Total | K12: =SUM(K2:K10) -> 10501.88 | L12: =SUM(L2:L10) -> 5582446.3 | N12: Total | O12: =SUM(O2:O9) -> 10501.88 | P12: =SUM(P2:P9) -> 5549846.3 | R12: Total | S12: =SUM(S2:S9) -> 0 | T12: =SUM(T2:T9) -> 0
B15: Compra/venta USD | J15: Análisis gastos e ingresos
B16: Nro. | C16: Ingresos | D16: Gastos | E16: Origen/Destino | F16: Concepto | G16: Descripción | H16: Fecha | J16: Concepto | K16: Acumulado egresos | L16: Acumulado ingresos | M16: Composición egresos | N16: Composición ingresos
B17: 1 | J17: Pago Claude/Cursor | K17: =SUMIF($F$24:$F$173,$J17,$D$24:$D$173) -> 0 | L17: =SUMIF($F$24:$F$173,$J17,$C$24:$C$173) -> 0 | M17: =IFERROR(K17/SUM(K$17:K$32),"") | N17: =IFERROR(L17/SUM(L$17:L$32),"")
B18: 2 | J18: Salidas a cenar/almorzar | K18: =SUMIF($F$24:$F$173,$J18,$C$24:$C$173)+SUMIF($F$24:$F$173,$J18,$D$24:$D$173) -> 0 | L18: =SUMIF($F$24:$F$173,$J18,$C$24:$C$173) -> 0 | M18: =IFERROR(K18/SUM(K$17:K$32),"") | N18: =IFERROR(L18/SUM(L$17:L$32),"")
B19: 3 | J19: Salidas a desyunar/merendar | K19: =SUMIF($F$24:$F$173,$J19,$C$24:$C$173)+SUMIF($F$24:$F$173,$J19,$D$24:$D$173) -> 0 | L19: =SUMIF($F$24:$F$173,$J19,$C$24:$C$173) -> 0 | M19: =IFERROR(K19/SUM(K$17:K$32),"") | N19: =IFERROR(L19/SUM(L$17:L$32),"")
J20: Salidas a tomar algo | K20: =SUMIF($F$24:$F$173,$J20,$C$24:$C$173)+SUMIF($F$24:$F$173,$J20,$D$24:$D$173) -> 0 | L20: =SUMIF($F$24:$F$173,$J20,$C$24:$C$173) -> 0 | M20: =IFERROR(K20/SUM(K$17:K$32),"") | N20: =IFERROR(L20/SUM(L$17:L$32),"")
J21: Fiestas | K21: =SUMIF($F$24:$F$173,$J21,$C$24:$C$173)+SUMIF($F$24:$F$173,$J21,$D$24:$D$173) -> 0 | L21: =SUMIF($F$24:$F$173,$J21,$C$24:$C$173) -> 0 | M21: =IFERROR(K21/SUM(K$17:K$32),"") | N21: =IFERROR(L21/SUM(L$17:L$32),"")
B22: Movimientos en ARS | J22: Auto | K22: =SUMIF($F$24:$F$173,$J22,$C$24:$C$173)+SUMIF($F$24:$F$173,$J22,$D$24:$D$173) -> 0 | L22: =SUMIF($F$24:$F$173,$J22,$C$24:$C$173) -> 0 | M22: =IFERROR(K22/SUM(K$17:K$32),"") | N22: =IFERROR(L22/SUM(L$17:L$32),"")
B23: Nro. | C23: Ingresos | D23: Gastos | E23: Origen/Destino | F23: Concepto | G23: Descripción | H23: Fecha | J23: Farmacia/Cosméticos | K23: =SUMIF($F$24:$F$173,$J23,$C$24:$C$173)+SUMIF($F$24:$F$173,$J23,$D$24:$D$173) -> 0 | L23: =SUMIF($F$24:$F$173,$J23,$C$24:$C$173) -> 0 | M23: =IFERROR(K23/SUM(K$17:K$32),"") | N23: =IFERROR(L23/SUM(L$17:L$32),"")
B24: 1 | J24: Ropa | K24: =SUMIF($F$24:$F$173,$J24,$C$24:$C$173)+SUMIF($F$24:$F$173,$J24,$D$24:$D$173) -> 0 | L24: =SUMIF($F$24:$F$173,$J24,$C$24:$C$173) -> 0 | M24: =IFERROR(K24/SUM(K$17:K$32),"") | N24: =IFERROR(L24/SUM(L$17:L$32),"")
B25: 2 | J25: Súper | K25: =SUMIF($F$24:$F$173,$J25,$C$24:$C$173)+SUMIF($F$24:$F$173,$J25,$D$24:$D$173) -> 0 | L25: =SUMIF($F$24:$F$173,$J25,$C$24:$C$173) -> 0 | M25: =IFERROR(K25/SUM(K$17:K$32),"") | N25: =IFERROR(L25/SUM(L$17:L$32),"")
B26: 3 | J26: Delivery | K26: =SUMIF($F$24:$F$173,$J26,$C$24:$C$173)+SUMIF($F$24:$F$173,$J26,$D$24:$D$173) -> 0 | L26: =SUMIF($F$24:$F$173,$J26,$C$24:$C$173) -> 0 | M26: =IFERROR(K26/SUM(K$17:K$32),"") | N26: =IFERROR(L26/SUM(L$17:L$32),"")
B27: 4 | J27: Regalos | K27: =SUMIF($F$24:$F$173,$J27,$C$24:$C$173)+SUMIF($F$24:$F$173,$J27,$D$24:$D$173) -> 0 | L27: =SUMIF($F$24:$F$173,$J27,$C$24:$C$173) -> 0 | M27: =IFERROR(K27/SUM(K$17:K$32),"") | N27: =IFERROR(L27/SUM(L$17:L$32),"")
B28: 5 | J28: Entradas fiestas/conciertos | K28: =SUMIF($F$24:$F$173,$J28,$C$24:$C$173)+SUMIF($F$24:$F$173,$J28,$D$24:$D$173) -> 0 | L28: =SUMIF($F$24:$F$173,$J28,$C$24:$C$173) -> 0 | M28: =IFERROR(K28/SUM(K$17:K$32),"") | N28: =IFERROR(L28/SUM(L$17:L$32),"")
B29: 6 | J29: Pago de honorarios Quantum | K29: =SUMIF($F$24:$F$173,$J29,$C$24:$C$173)+SUMIF($F$24:$F$173,$J29,$D$24:$D$173) -> 0 | L29: =SUMIF($F$24:$F$173,$J29,$C$24:$C$173) -> 0 | M29: =IFERROR(K29/SUM(K$17:K$32),"") | N29: =IFERROR(L29/SUM(L$17:L$32),"")
B30: 7 | J30: Pago de honorarios Axis | K30: =SUMIF($F$24:$F$173,$J30,$C$24:$C$173)+SUMIF($F$24:$F$173,$J30,$D$24:$D$173) -> 0 | L30: =SUMIF($F$24:$F$173,$J30,$C$24:$C$173) -> 0 | M30: =IFERROR(K30/SUM(K$17:K$32),"") | N30: =IFERROR(L30/SUM(L$17:L$32),"")
B31: 8 | J31: Otros honorarios | K31: =SUMIF($F$24:$F$173,$J31,$C$24:$C$173)+SUMIF($F$24:$F$173,$J31,$D$24:$D$173) -> 0 | L31: =SUMIF($F$24:$F$173,$J31,$C$24:$C$173) -> 0 | M31: =IFERROR(K31/SUM(K$17:K$32),"") | N31: =IFERROR(L31/SUM(L$17:L$32),"")
B32: 9 | J32: Ahorros/inversiones | K32: =SUMIF($F$24:$F$173,$J32,$C$24:$C$173)+SUMIF($F$24:$F$173,$J32,$D$24:$D$173) -> 0 | L32: =SUMIF($F$24:$F$173,$J32,$C$24:$C$173) -> 0 | M32: =IFERROR(K32/SUM(K$17:K$32),"") | N32: =IFERROR(L32/SUM(L$17:L$32),"")
B33: 10 | J33: Pago tarjetas de crédito | K33: =SUMIF($F$24:$F$173,$J33,$C$24:$C$173)+SUMIF($F$24:$F$173,$J33,$D$24:$D$173) -> 0 | L33: =SUMIF($F$24:$F$173,$J33,$C$24:$C$173) -> 0 | M33: =IFERROR(K33/SUM(K$17:K$32),"") | N33: =IFERROR(L33/SUM(L$17:L$32),"")
B34: 11
B35: 12 | J35: Superfondos Santander
B36: 13 | J36: Superfondos Santander | K36: 46272 | L36: 46279 | M36: 46286 | N36: 46293
B37: 14 | J37: Calculado | K37: =$L$5+SUMIFS($C$24:$C$173,$E$24:$E$173,$N5,$H$24:$H$173,"<="&K$36)+SUMIFS($D$24:$D$173,$E$24:$E$173,$N5,$H$24:$H$173,"<="&K$36) -> 3896368.8 | L37: =$L$5+SUMIFS($C$24:$C$173,$E$24:$E$173,$N5,$H$24:$H$173,"<"&L$36)+SUMIFS($D$24:$D$173,$E$24:$E$173,$N5,$H$24:$H$173,"<="&L$36) -> 3896368.8 | M37: =$L$5+SUMIFS($C$24:$C$173,$E$24:$E$173,$N5,$H$24:$H$173,"<"&M$36)+SUMIFS($D$24:$D$173,$E$24:$E$173,$N5,$H$24:$H$173,"<="&M$36) -> 3896368.8 | N37: =$L$5+SUMIFS($C$24:$C$173,$E$24:$E$173,$N5,$H$24:$H$173,"<"&N$36)+SUMIFS($D$24:$D$173,$E$24:$E$173,$N5,$H$24:$H$173,"<="&N$36) -> 3896368.8
B38: 15 | J38: Real
B39: 16 | J39: Rendimiento (neto) | K39: =IF(K38="","",K38-K37) | L39: =IF(L38="","",L38-L37) | M39: =IF(M38="","",M38-M37) | N39: =IF(N38="","",N38-N37)
B40: 17 | J40: Rendimiento (%) | K40: =IF(K39="","",((K38-K37)/K37)) | L40: =IF(L39="","",((L38-L37)/L37)) | M40: =IF(M39="","",((M38-M37)/M37)) | N40: =IF(N39="","",((N38-N37)/N37))
B41: 18
B42: 19 | J42: Petrini
B43: 20 | J43: Fecha | K43: =K36 -> 46272 | L43: =L36 -> 46279 | M43: =M36 -> 46286 | N43: =N36 -> 46293
...

Sheet Gastos noviembre
B1: Datos del periodo | J1: Tenencia - Inicio | K1: USD | L1: ARS | N1: Tenencia - Fin | O1: USD | P1: ARS | R1: Diferencia | S1: USD | T1: ARS
B2: Año: | C2: 2026 | J2: Regalo recibida | K2: ='Gastos octubre'!O2 -> 10000 | L2: =K2*D7 -> 0 | N2: Regalo recibida | O2: =K2+SUMIF($E$24:$E$173,$N2,$C$24:$C$173)+SUMIF($E$24:$E$173,$N2,$D$24:$D$173) -> 10000 | P2: =O2*$D$7 -> 0 | R2: Regalo recibida | S2: =IFERROR(IF(O2>K2,O2-K2,K2-O2),0) -> 0 | T2: =IFERROR(IF(P2>L2,P2-L2,L2-P2),0) -> 0
B3: Mes: | C3: noviembre | J3: Caja de seguridad | K3: ='Gastos octubre'!O3 -> 500 | L3: =K3*D7 -> 0 | N3: Caja de seguridad | O3: =K3 -> 500 | P3: =L3+SUMIF($E$24:$E$173,$N3,$C$24:$C$173)+SUMIF($E$24:$E$173,$N3,$D$24:$D$173) -> 0 | R3: Caja de seguridad | S3: =IFERROR(IF(O3>K3,O3-K3,K3-O3),0) -> 0 | T3: =IFERROR(IF(P3>L3,P3-L3,L3-P3),0) -> 0
B4: Cantidad de días: | C4: =DAY(EOMONTH(DATE($C$2,MATCH($C$3,{"enero";"febrero";"marzo";"abril";"mayo";"junio";"julio";"agosto";"septiembre";"octubre";"noviembre";"diciembre"},0),1),0)) -> 30 | J4: Cta. Comitente Petrini | K4: ='Gastos octubre'!O4 | L4: ='Gastos octubre'!P4 -> 1647262.6 | N4: Cta. Comitente Petrini | O4: =IFERROR(P4/$C$8,"") | P4: =L4+SUMIF($E$24:$E$173,$N4,$C$24:$C$173)+SUMIF($E$24:$E$173,$N4,$D$24:$D$173) -> 1647262.6 | R4: Cta. Comitente Petrini | S4: =IFERROR(IF(O4>K4,O4-K4,K4-O4),0) -> 0 | T4: =IFERROR(IF(P4>L4,P4-L4,L4-P4),0) -> 0
J5: Superfondos Santander | K5: ='Gastos octubre'!O5 | L5: ='Gastos octubre'!P5 -> 3896368.8 | N5: Superfondos Santander | O5: =IFERROR(P5/$C$8,"") | P5: =L5+SUMIF($E$24:$E$173,$N5,$C$24:$C$173)+SUMIF($E$24:$E$173,$N5,$D$24:$D$173) -> 3896368.8 | R5: Superfondos Santander | S5: =IFERROR(IF(O5>K5,O5-K5,K5-O5),0) -> 0 | T5: =IFERROR(IF(P5>L5,P5-L5,L5-P5),0) -> 0
B6: Tc | C6: Compra | D6: Venta | J6: Caja de Ahorro Santander (ARS) | K6: ='Gastos octubre'!O6 | L6: ='Gastos octubre'!P6 -> 5648.43 | N6: Caja de Ahorro Santander (ARS) | O6: =IFERROR(P6/$C$8,"") | P6: =L6+SUMIF($E$24:$E$173,$N6,$C$24:$C$173)+SUMIF($E$24:$E$173,$N6,$D$24:$D$173) -> 5648.43 | R6: Caja de Ahorro Santander (ARS) | S6: =IFERROR(IF(O6>K6,O6-K6,K6-O6),0) -> 0 | T6: =IFERROR(IF(P6>L6,P6-L6,L6-P6),0) -> 0
B7: =DATE($C$2,MATCH($C$3,{"enero";"febrero";"marzo";"abril";"mayo";"junio";"julio";"agosto";"septiembre";"octubre";"noviembre";"diciembre"},0),1) -> 46327 | J7: Caja de Ahorro Santander (USD) | K7: ='Gastos octubre'!O7 -> 1.88 | L7: =K7*D7 -> 0 | N7: Caja de Ahorro Santander (USD) | O7: =K7+SUM(C17:C19)+SUM(D17:D19) -> 1.88 | P7: =O7*$D$8 -> 0 | R7: Caja de Ahorro Santander (USD) | S7: =IFERROR(IF(O7>K7,O7-K7,K7-O7),0) -> 0 | T7: =IFERROR(IF(P7>L7,P7-L7,L7-P7),0) -> 0
B8: =DATE($C$2,MATCH($C$3,{"enero";"febrero";"marzo";"abril";"mayo";"junio";"julio";"agosto";"septiembre";"octubre";"noviembre";"diciembre"},0),C4) -> 46356 | J8: Mercado Pago | K8: ='Gastos octubre'!O8 | L8: ='Gastos octubre'!P8 -> 565.09 | N8: Mercado Libre | O8: =IFERROR(P8/$C$8,"") | P8: =L8+SUMIF($E$24:$E$173,$N8,$C$24:$C$173)+SUMIF($E$24:$E$173,$N8,$D$24:$D$173) -> 565.09 | R8: Mercado Libre | S8: =IFERROR(IF(O8>K8,O8-K8,K8-O8),0) -> 0 | T8: =IFERROR(IF(P8>L8,P8-L8,L8-P8),0) -> 0
J9: Brubank | K9: ='Gastos octubre'!O9 | L9: ='Gastos octubre'!P9 -> 1.36 | N9: Brubank | O9: =IFERROR(P9/$C$8,"") | P9: =L9+SUMIF($E$24:$E$173,$N9,$C$24:$C$173)+SUMIF($E$24:$E$173,$N9,$D$24:$D$173) -> 1.36 | R9: Brubank | S9: =IFERROR(IF(O9>K9,O9-K9,K9-O9),0) -> 0 | T9: =IFERROR(IF(P9>L9,P9-L9,L9-P9),0) -> 0
J10: Efectivo | K10: ='Gastos octubre'!O10 | L10: ='Gastos octubre'!P10 -> 32600 | N10: Efectivo | O10: =IFERROR(P10/$C$8,"") | P10: =L10+SUMIF($E$24:$E$173,$N10,$C$24:$C$173)+SUMIF($E$24:$E$173,$N10,$D$24:$D$173) -> 32600 | R10: Efectivo | S10: =IFERROR(IF(O10>K10,O10-K10,K10-O10),0) -> 0 | T10: =IFERROR(IF(P10>L10,P10-L10,L10-P10),0) -> 0
J12: Total | K12: =SUM(K2:K10) -> 10501.88 | L12: =SUM(L2:L10) -> 5582446.3 | N12: Total | O12: =SUM(O2:O9) -> 10501.88 | P12: =SUM(P2:P9) -> 5549846.3 | R12: Total | S12: =SUM(S2:S9) -> 0 | T12: =SUM(T2:T9) -> 0
B15: Compra/venta USD | J15: Análisis gastos e ingresos
B16: Nro. | C16: Ingresos | D16: Gastos | E16: Origen/Destino | F16: Concepto | G16: Descripción | H16: Fecha | J16: Concepto | K16: Acumulado egresos | L16: Acumulado ingresos | M16: Composición egresos | N16: Composición ingresos
B17: 1 | J17: Pago Claude/Cursor | K17: =SUMIF($F$24:$F$173,$J17,$D$24:$D$173) -> 0 | L17: =SUMIF($F$24:$F$173,$J17,$C$24:$C$173) -> 0 | M17: =IFERROR(K17/SUM(K$17:K$32),"") | N17: =IFERROR(L17/SUM(L$17:L$32),"")
B18: 2 | J18: Salidas a cenar/almorzar | K18: =SUMIF($F$24:$F$173,$J18,$C$24:$C$173)+SUMIF($F$24:$F$173,$J18,$D$24:$D$173) -> 0 | L18: =SUMIF($F$24:$F$173,$J18,$C$24:$C$173) -> 0 | M18: =IFERROR(K18/SUM(K$17:K$32),"") | N18: =IFERROR(L18/SUM(L$17:L$32),"")
B19: 3 | J19: Salidas a desyunar/merendar | K19: =SUMIF($F$24:$F$173,$J19,$C$24:$C$173)+SUMIF($F$24:$F$173,$J19,$D$24:$D$173) -> 0 | L19: =SUMIF($F$24:$F$173,$J19,$C$24:$C$173) -> 0 | M19: =IFERROR(K19/SUM(K$17:K$32),"") | N19: =IFERROR(L19/SUM(L$17:L$32),"")
J20: Salidas a tomar algo | K20: =SUMIF($F$24:$F$173,$J20,$C$24:$C$173)+SUMIF($F$24:$F$173,$J20,$D$24:$D$173) -> 0 | L20: =SUMIF($F$24:$F$173,$J20,$C$24:$C$173) -> 0 | M20: =IFERROR(K20/SUM(K$17:K$32),"") | N20: =IFERROR(L20/SUM(L$17:L$32),"")
J21: Fiestas | K21: =SUMIF($F$24:$F$173,$J21,$C$24:$C$173)+SUMIF($F$24:$F$173,$J21,$D$24:$D$173) -> 0 | L21: =SUMIF($F$24:$F$173,$J21,$C$24:$C$173) -> 0 | M21: =IFERROR(K21/SUM(K$17:K$32),"") | N21: =IFERROR(L21/SUM(L$17:L$32),"")
B22: Movimientos en ARS | J22: Auto | K22: =SUMIF($F$24:$F$173,$J22,$C$24:$C$173)+SUMIF($F$24:$F$173,$J22,$D$24:$D$173) -> 0 | L22: =SUMIF($F$24:$F$173,$J22,$C$24:$C$173) -> 0 | M22: =IFERROR(K22/SUM(K$17:K$32),"") | N22: =IFERROR(L22/SUM(L$17:L$32),"")
B23: Nro. | C23: Ingresos | D23: Gastos | E23: Origen/Destino | F23: Concepto | G23: Descripción | H23: Fecha | J23: Farmacia/Cosméticos | K23: =SUMIF($F$24:$F$173,$J23,$C$24:$C$173)+SUMIF($F$24:$F$173,$J23,$D$24:$D$173) -> 0 | L23: =SUMIF($F$24:$F$173,$J23,$C$24:$C$173) -> 0 | M23: =IFERROR(K23/SUM(K$17:K$32),"") | N23: =IFERROR(L23/SUM(L$17:L$32),"")
B24: 1 | J24: Ropa | K24: =SUMIF($F$24:$F$173,$J24,$C$24:$C$173)+SUMIF($F$24:$F$173,$J24,$D$24:$D$173) -> 0 | L24: =SUMIF($F$24:$F$173,$J24,$C$24:$C$173) -> 0 | M24: =IFERROR(K24/SUM(K$17:K$32),"") | N24: =IFERROR(L24/SUM(L$17:L$32),"")
B25: 2 | J25: Súper | K25: =SUMIF($F$24:$F$173,$J25,$C$24:$C$173)+SUMIF($F$24:$F$173,$J25,$D$24:$D$173) -> 0 | L25: =SUMIF($F$24:$F$173,$J25,$C$24:$C$173) -> 0 | M25: =IFERROR(K25/SUM(K$17:K$32),"") | N25: =IFERROR(L25/SUM(L$17:L$32),"")
B26: 3 | J26: Delivery | K26: =SUMIF($F$24:$F$173,$J26,$C$24:$C$173)+SUMIF($F$24:$F$173,$J26,$D$24:$D$173) -> 0 | L26: =SUMIF($F$24:$F$173,$J26,$C$24:$C$173) -> 0 | M26: =IFERROR(K26/SUM(K$17:K$32),"") | N26: =IFERROR(L26/SUM(L$17:L$32),"")
B27: 4 | J27: Regalos | K27: =SUMIF($F$24:$F$173,$J27,$C$24:$C$173)+SUMIF($F$24:$F$173,$J27,$D$24:$D$173) -> 0 | L27: =SUMIF($F$24:$F$173,$J27,$C$24:$C$173) -> 0 | M27: =IFERROR(K27/SUM(K$17:K$32),"") | N27: =IFERROR(L27/SUM(L$17:L$32),"")
B28: 5 | J28: Entradas fiestas/conciertos | K28: =SUMIF($F$24:$F$173,$J28,$C$24:$C$173)+SUMIF($F$24:$F$173,$J28,$D$24:$D$173) -> 0 | L28: =SUMIF($F$24:$F$173,$J28,$C$24:$C$173) -> 0 | M28: =IFERROR(K28/SUM(K$17:K$32),"") | N28: =IFERROR(L28/SUM(L$17:L$32),"")
B29: 6 | J29: Pago de honorarios Quantum | K29: =SUMIF($F$24:$F$173,$J29,$C$24:$C$173)+SUMIF($F$24:$F$173,$J29,$D$24:$D$173) -> 0 | L29: =SUMIF($F$24:$F$173,$J29,$C$24:$C$173) -> 0 | M29: =IFERROR(K29/SUM(K$17:K$32),"") | N29: =IFERROR(L29/SUM(L$17:L$32),"")
B30: 7 | J30: Pago de honorarios Axis | K30: =SUMIF($F$24:$F$173,$J30,$C$24:$C$173)+SUMIF($F$24:$F$173,$J30,$D$24:$D$173) -> 0 | L30: =SUMIF($F$24:$F$173,$J30,$C$24:$C$173) -> 0 | M30: =IFERROR(K30/SUM(K$17:K$32),"") | N30: =IFERROR(L30/SUM(L$17:L$32),"")
B31: 8 | J31: Otros honorarios | K31: =SUMIF($F$24:$F$173,$J31,$C$24:$C$173)+SUMIF($F$24:$F$173,$J31,$D$24:$D$173) -> 0 | L31: =SUMIF($F$24:$F$173,$J31,$C$24:$C$173) -> 0 | M31: =IFERROR(K31/SUM(K$17:K$32),"") | N31: =IFERROR(L31/SUM(L$17:L$32),"")
B32: 9 | J32: Ahorros/inversiones | K32: =SUMIF($F$24:$F$173,$J32,$C$24:$C$173)+SUMIF($F$24:$F$173,$J32,$D$24:$D$173) -> 0 | L32: =SUMIF($F$24:$F$173,$J32,$C$24:$C$173) -> 0 | M32: =IFERROR(K32/SUM(K$17:K$32),"") | N32: =IFERROR(L32/SUM(L$17:L$32),"")
B33: 10 | J33: Pago tarjetas de crédito | K33: =SUMIF($F$24:$F$173,$J33,$C$24:$C$173)+SUMIF($F$24:$F$173,$J33,$D$24:$D$173) -> 0 | L33: =SUMIF($F$24:$F$173,$J33,$C$24:$C$173) -> 0 | M33: =IFERROR(K33/SUM(K$17:K$32),"") | N33: =IFERROR(L33/SUM(L$17:L$32),"")
B34: 11
B35: 12 | J35: Superfondos Santander
B36: 13 | J36: Superfondos Santander | K36: 46272 | L36: 46279 | M36: 46286 | N36: 46293
